<?xml version="1.0" ?>
<!-- =================================================================================== -->
<!-- |    This document was autogenerated by xacro from robotarm_description.xacro     | -->
<!-- |    EDITING THIS FILE BY HAND IS NOT RECOMMENDED                                 | -->
<!-- =================================================================================== -->
<robot name="robotarm" xmlns:xacro="http://www.ros.org/wiki/xacro">
  <!-- Space btw top of beam and the each joint -->
  <!--xacro:property name="camera_name" value="rgbd" /-->
  <!-- Size of square 'camera' box -->
  <!--xacro:property name="frame_name" value="rgbd_depth" /-->
  <!-- Size of square 'camera' box -->
  <!-- ros_control plugin -->
  <gazebo>
    <plugin filename="libgazebo_ros_control.so" name="gazebo_ros_control">
      <robotNamespace>/bmirobot</robotNamespace>
      <robotSimType>gazebo_ros_control/DefaultRobotHWSim</robotSimType>
    </plugin>
  </gazebo>
  <!-- Link1 -->
  <gazebo reference="link1">
    <material>Gazebo/Orange</material>
  </gazebo>
  <!-- Link2 -->
  <gazebo reference="link2">
    <mu1>0.2</mu1>
    <mu2>0.2</mu2>
    <material>Gazebo/Black</material>
  </gazebo>
  <!-- Link3 -->
  <gazebo reference="link3">
    <mu1>0.2</mu1>
    <mu2>0.2</mu2>
    <material>Gazebo/Orange</material>
  </gazebo>
  <!-- Link4 -->
  <gazebo reference="link4">
    <mu1>0.2</mu1>
    <mu2>0.2</mu2>
    <material>Gazebo/Black</material>
  </gazebo>
  <!-- Link5 -->
  <gazebo reference="link5">
    <mu1>0.2</mu1>
    <mu2>0.2</mu2>
    <material>Gazebo/Orange</material>
  </gazebo>
  <!-- Link6 -->
  <gazebo reference="link6">
    <mu1>0.2</mu1>
    <mu2>0.2</mu2>
    <material>Gazebo/Black</material>
  </gazebo>
  <!-- Link7 -->
  <gazebo reference="link7">
    <mu1>0.2</mu1>
    <mu2>0.2</mu2>
    <material>Gazebo/Orange</material>
  </gazebo>
  <!-- camera -->
  <gazebo reference="camera_link">
    <sensor name="camera1" type="camera">
      <update_rate>5.0</update_rate>
      <camera name="head">
        <horizontal_fov>1.3962634</horizontal_fov>
        <image>
          <width>800</width>
          <height>800</height>
          <format>R8G8B8</format>
        </image>
        <clip>
          <near>0.02</near>
          <far>300</far>
        </clip>
        <noise>
          <type>gaussian</type>
          <!-- Noise is sampled independently per pixel on each frame.
               That pixel's noise value is added to each of its color
               channels, which at that point lie in the range [0,1]. -->
          <mean>0.0</mean>
          <stddev>0.007</stddev>
        </noise>
      </camera>
      <plugin filename="libgazebo_ros_camera.so" name="camera_controller">
        <alwaysOn>true</alwaysOn>
        <updateRate>0.0</updateRate>
        <cameraName>rrbot/camera1</cameraName>
        <imageTopicName>image_raw</imageTopicName>
        <cameraInfoTopicName>camera_info</cameraInfoTopicName>
        <frameName>camera_link</frameName>
        <hackBaseline>0.07</hackBaseline>
        <distortionK1>0.0</distortionK1>
        <distortionK2>0.0</distortionK2>
        <distortionK3>0.0</distortionK3>
        <distortionT1>0.0</distortionT1>
        <distortionT2>0.0</distortionT2>
      </plugin>
    </sensor>
  </gazebo>
  <gazebo reference="rgbd_link">
    <sensor name="rgbd1" type="depth">
      <always_on>1</always_on>
      <update_rate>20.0</update_rate>
      <visualize>false</visualize>
      <camera>
        <horizontal_fov>1.047</horizontal_fov>
        <image>
          <width>640</width>
          <height>480</height>
          <format>B8G8R8</format>
        </image>
        <depth_camera>

            </depth_camera>
        <clip>
          <near>0.1</near>
          <far>4</far>
        </clip>
      </camera>
      <plugin filename="libgazebo_ros_openni_kinect.so" name="rgbd_controller">
        <baseline>0.2</baseline>
        <alwaysOn>true</alwaysOn>
        <updateRate>20.0</updateRate>
        <cameraName>camera</cameraName>
        <imageTopicName>/camera/rgb/image_raw</imageTopicName>
        <cameraInfoTopicName>/camera/rgb/camera_info</cameraInfoTopicName>
        <depthImageTopicName>/camera/depth/image_raw</depthImageTopicName>
        <depthImageInfoTopicName>/camera/depth/camera_info</depthImageInfoTopicName>
        <pointCloudTopicName>/camera/depth/points</pointCloudTopicName>
        <frameName>camera_depth_optical_frame</frameName>
        <pointCloudCutoff>0.5</pointCloudCutoff>
        <distortionK1>0</distortionK1>
        <distortionK2>0</distortionK2>
        <distortionK3>0</distortionK3>
        <distortionT1>0</distortionT1>
        <distortionT2>0</distortionT2>
        <CxPrime>0</CxPrime>
        <Cx>0</Cx>
        <Cy>0</Cy>
        <focalLength>0</focalLength>
        <hackBaseline>0</hackBaseline>
      </plugin>
    </sensor>
  </gazebo>
  <gazebo>
    <plugin filename="libgazebo_grasp_fix.so" name="gazebo_grasp_fix">
      <arm>
        <arm_name>bmirobot</arm_name>
        <palm_link>link8</palm_link>
        <gripper_link>hand_1</gripper_link>
        <gripper_link>hand_4</gripper_link>
      </arm>
      <forces_angle_tolerance>90</forces_angle_tolerance>
      <update_rate>4</update_rate>
      <grip_count_threshold>2</grip_count_threshold>
      <max_grip_count>4</max_grip_count>
      <release_tolerance>0.003</release_tolerance>
      <disable_collisions_on_attach>true</disable_collisions_on_attach>
      <contact_topic>__default_topic__</contact_topic>
    </plugin>
  </gazebo>
  <material name="black">
    <color rgba="0.0 0.0 0.0 1.0"/>
  </material>
  <material name="blue">
    <color rgba="0.0 0.0 0.8 1.0"/>
  </material>
  <material name="green">
    <color rgba="0.0 0.8 0.0 1.0"/>
  </material>
  <material name="grey">
    <color rgba="0.2 0.2 0.2 1.0"/>
  </material>
  <material name="orange">
    <color rgba="1.0 0.423529411765 0.0392156862745 1.0"/>
  </material>
  <material name="brown">
    <color rgba="0.870588235294 0.811764705882 0.764705882353 1.0"/>
  </material>
  <material name="red">
    <color rgba="0.8 0.0 0.0 1.0"/>
  </material>
  <material name="white">
    <color rgba="1.0 1.0 1.0 1.0"/>
  </material>
  <!-- Used for fixing robot to Gazebo 'base_link' -->
  <link name="world"/>
  <joint name="fixed" type="fixed">
    <parent link="world"/>
    <child link="odom_combined"/>
  </joint>
  <link name="odom_combined"/>
  <joint name="virtual_joint" type="fixed">
    <parent link="odom_combined"/>
    <child link="base_link"/>
    <origin rpy="0 0 0" xyz="0 0 0.45"/>
  </joint>
  <link name="base_link"/>
  <joint name="rightvirtual_joint" type="fixed">
    <parent link="base_link"/>
    <child link="right_link1"/>
    <origin rpy="0 0 0" xyz="0.22 0 0"/>
  </joint>
  <joint name="leftvirtual_joint" type="fixed">
    <parent link="base_link"/>
    <child link="left_link1"/>
    <origin rpy="0 0 3.14159265359" xyz="0.03 0 0"/>
  </joint>
  <link name="right_link1">
    <visual>
      <geometry>
        <mesh filename="package://bmirobot_description/modle/stl_V5/baselink.dae"/>
      </geometry>
      <origin rpy="0 0 0" xyz="0 0 0"/>
      <material name="red"/>
    </visual>
    <collision>
      <geometry>
        <mesh filename="package://bmirobot_description/modle/stl_V5/baselink.dae"/>
      </geometry>
      <origin rpy="0 0 0" xyz="0 0 0"/>
    </collision>
    <inertial>
      <origin rpy="0 0 0" xyz="0 0 1"/>
      <mass value="1"/>
      <inertia ixx="1.0" ixy="0.0" ixz="0.0" iyy="1.0" iyz="0.0" izz="1.0"/>
    </inertial>
  </link>
  <link name="right_link2">
    <visual>
      <geometry>
        <mesh filename="package://bmirobot_description/modle/stl_V5/link1.dae"/>
      </geometry>
      <origin rpy="0 0 0" xyz="0 0 0"/>
      <material name="white"/>
    </visual>
    <collision>
      <geometry>
        <mesh filename="package://bmirobot_description/modle/stl_V5/link1.dae"/>
      </geometry>
      <origin rpy="0 0 0" xyz="0 0 0"/>
    </collision>
    <inertial>
      <origin rpy="0 0 0" xyz="0 0 1"/>
      <mass value="1"/>
      <inertia ixx="1.0" ixy="0.0" ixz="0.0" iyy="1.0" iyz="0.0" izz="1.0"/>
    </inertial>
  </link>
  <link name="right_link3">
    <visual>
      <geometry>
        <mesh filename="package://bmirobot_description/modle/stl_V5/link2.dae"/>
      </geometry>
      <origin rpy="0 0 0" xyz="0 0 0"/>
      <material name="blue"/>
    </visual>
    <collision>
      <geometry>
        <mesh filename="package://bmirobot_description/modle/stl_V5/link2.dae"/>
      </geometry>
      <origin rpy="0 0 0" xyz="0 0 0"/>
    </collision>
    <inertial>
      <origin rpy="0 0 0" xyz="0 0 1"/>
      <mass value="1"/>
      <inertia ixx="1.0" ixy="0.0" ixz="0.0" iyy="1.0" iyz="0.0" izz="1.0"/>
    </inertial>
  </link>
  <link name="right_link4">
    <visual>
      <geometry>
        <mesh filename="package://bmirobot_description/modle/stl_V5/link3.dae"/>
      </geometry>
      <origin rpy="0 0 0" xyz="0 0 0"/>
      <material name="orange"/>
    </visual>
    <collision>
      <geometry>
        <mesh filename="package://bmirobot_description/modle/stl_V5/link3.dae"/>
      </geometry>
      <origin rpy="0 0 0" xyz="0 0 0"/>
    </collision>
    <inertial>
      <origin rpy="0 0 0" xyz="0 0 1"/>
      <mass value="1"/>
      <inertia ixx="1.0" ixy="0.0" ixz="0.0" iyy="1.0" iyz="0.0" izz="1.0"/>
    </inertial>
  </link>
  <link name="right_link5">
    <visual>
      <geometry>
        <mesh filename="package://bmirobot_description/modle/stl_V5/link4.dae"/>
      </geometry>
      <origin rpy="0 0 0" xyz="0 0 0"/>
      <material name="blue"/>
    </visual>
    <collision>
      <geometry>
        <mesh filename="package://bmirobot_description/modle/stl_V5/link4.dae"/>
      </geometry>
      <origin rpy="0 0 0" xyz="0 0 0"/>
    </collision>
    <inertial>
      <origin rpy="0 0 0" xyz="0 0 1"/>
      <mass value="1"/>
      <inertia ixx="1.0" ixy="0.0" ixz="0.0" iyy="1.0" iyz="0.0" izz="1.0"/>
    </inertial>
  </link>
  <link name="right_link6">
    <visual>
      <geometry>
        <mesh filename="package://bmirobot_description/modle/stl_V5/link5.dae"/>
      </geometry>
      <origin rpy="0 0 0" xyz="0 0 0"/>
      <material name="orange"/>
    </visual>
    <collision>
      <geometry>
        <mesh filename="package://bmirobot_description/modle/stl_V5/link5.dae"/>
      </geometry>
      <origin rpy="0 0 0" xyz="0 0 0"/>
    </collision>
    <inertial>
      <origin rpy="0 0 0" xyz="0 0 1"/>
      <mass value="1"/>
      <inertia ixx="1.0" ixy="0.0" ixz="0.0" iyy="1.0" iyz="0.0" izz="1.0"/>
    </inertial>
  </link>
  <link name="right_link7">
    <visual>
      <geometry>
        <mesh filename="package://bmirobot_description/modle/stl_V5/link6.dae"/>
      </geometry>
      <origin rpy="0 0 0" xyz="0 0 0"/>
      <material name="blue"/>
    </visual>
    <collision>
      <geometry>
        <mesh filename="package://bmirobot_description/modle/stl_V5/link6.dae"/>
      </geometry>
      <origin rpy="0 0 0" xyz="0 0 0"/>
    </collision>
    <inertial>
      <origin rpy="0 0 0" xyz="0 0 1"/>
      <mass value="1"/>
      <inertia ixx="1.0" ixy="0.0" ixz="0.0" iyy="1.0" iyz="0.0" izz="1.0"/>
    </inertial>
  </link>
  <link name="right_link8">
    <visual>
      <geometry>
        <mesh filename="package://bmirobot_description/modle/stl_V5/link7.dae"/>
      </geometry>
      <origin rpy="0 0 0" xyz="0 0 0"/>
      <material name="red"/>
    </visual>
    <collision>
      <geometry>
        <mesh filename="package://bmirobot_description/modle/stl_V5/link7.dae"/>
      </geometry>
      <origin rpy="0 0 0" xyz="0 0 0"/>
    </collision>
    <inertial>
      <origin rpy="0 0 0" xyz="0 0 1"/>
      <mass value="1"/>
      <inertia ixx="1.0" ixy="0.0" ixz="0.0" iyy="1.0" iyz="0.0" izz="1.0"/>
    </inertial>
  </link>
  <link name="right_hand1">
    <contact>
      <lateral_friction value="10.0"/>
      <rolling_friction value="0.0"/>
      <inertia_scaling value="3.0"/>
      <contact_cfm value="0.0"/>
      <contact_erp value="1.0"/>
    </contact>
    <visual>
      <geometry>
        <mesh filename="package://bmirobot_description/modle/stl_V5/hand-1.dae"/>
      </geometry>
      <origin rpy="0 0 0" xyz="0 0 0"/>
      <material name="white"/>
    </visual>
    <collision>
      <geometry>
        <mesh filename="package://bmirobot_description/modle/stl_V5/hand-1.dae"/>
      </geometry>

      <origin rpy="0 0 0" xyz="0 0 0"/>
    </collision>
    <inertial>
      <origin rpy="0 0 0" xyz="0 0 1"/>
      <mass value="1"/>
      <inertia ixx="1.0" ixy="0.0" ixz="0.0" iyy="1.0" iyz="0.0" izz="1.0"/>
    </inertial>
  </link>
  <link name="right_hand2">
    <contact>
      <lateral_friction value="1.0"/>
      <rolling_friction value="0.0"/>
      <inertia_scaling value="3.0"/>
      <contact_cfm value="0.0"/>
      <contact_erp value="1.0"/>
    </contact>
    <visual>
      <geometry>
        <mesh filename="package://bmirobot_description/modle/stl_V5/hand-2.dae"/>
      </geometry>
      <origin rpy="0 0 0" xyz="0 0 0"/>
      <material name="white"/>
    </visual>
    <collision>
      <geometry>
        <mesh filename="package://bmirobot_description/modle/stl_V5/hand-2.dae"/>
      </geometry>
      <origin rpy="0 0 0" xyz="0 0 0"/>
    </collision>
    <inertial>
      <origin rpy="0 0 0" xyz="0 0 1"/>
      <mass value="1"/>
      <inertia ixx="1.0" ixy="0.0" ixz="0.0" iyy="1.0" iyz="0.0" izz="1.0"/>
    </inertial>
  </link>
  <joint name="right_joint1" type="revolute">
    <limit effort="1000.0" lower="-1.57079632679" upper="3.14159265359" velocity="9.42477796077"/>
    <origin rpy="0 0 0" xyz="0.081 0 0"/>
    <axis xyz="1 0 0"/>
    <parent link="right_link1"/>
    <child link="right_link2"/>
    <dynamics damping="0.7"/>
  </joint>
  <joint name="right_joint2" type="revolute">
    <limit effort="1000.0" lower="-3.14159265359" upper="0.174532925199" velocity="9.42477796077"/>
    <origin rpy="0 1.57079632679 0" xyz="0.040 0 0"/>
    <axis xyz="0 1 0"/>
    <parent link="right_link2"/>
    <child link="right_link3"/>
    <dynamics damping="0.7"/>
  </joint>
  <joint name="right_joint3" type="revolute">
    <limit effort="1000.0" lower="-1.57079632679" upper="1.57079632679" velocity="9.42477796077"/>
    <origin rpy="-1.57079632679 0 0" xyz="0.0555 0 0"/>
    <axis xyz="1 0 0"/>
    <parent link="right_link3"/>
    <child link="right_link4"/>
    <dynamics damping="0.7"/>
  </joint>
  <joint name="right_joint4" type="revolute">
    <limit effort="1000.0" lower="-0.872664625997" upper="2.09439510239" velocity="9.42477796077"/>
    <origin rpy="0 -1.57079632679 0" xyz="0.1945 0 0"/>
    <axis xyz="0 1 0"/>
    <parent link="right_link4"/>
    <child link="right_link5"/>
    <dynamics damping="0.7"/>
  </joint>
  <joint name="right_joint5" type="revolute">
    <limit effort="1000.0" lower="-3.14159265359" upper="1.74532925199" velocity="9.42477796077"/>
    <origin rpy="1.57079632679 0 0" xyz="0.037 0 0.000"/>
    <axis xyz="1 0 0"/>
    <parent link="right_link5"/>
    <child link="right_link6"/>
    <dynamics damping="0.7"/>
  </joint>
  <joint name="right_joint6" type="revolute">
    <limit effort="1000.0" lower="-1.2217304764" upper="1.57079632679" velocity="9.42477796077"/>
    <origin rpy="-1.57079632679 0 0" xyz="0.203 0 0"/>
    <axis xyz="0 1 0"/>
    <parent link="right_link6"/>
    <child link="right_link7"/>
    <dynamics damping="0.7"/>
  </joint>
  <joint name="right_joint7" type="revolute">
    <limit effort="1000.0" lower="-1.57079632679" upper="1.57079632679" velocity="9.42477796077"/>
    <origin rpy="0.0 0 0" xyz="0.0 0 0"/>
    <axis xyz="0 0 1"/>
    <parent link="right_link7"/>
    <child link="right_link8"/>
    <dynamics damping="0.7"/>
  </joint>
  <joint name="right_hand_joint1" type="revolute">
    <limit effort="1000.0" lower="-1.57079632679" upper="1.57079632679" velocity="9.42477796077"/>
    <origin rpy="0 0 0" xyz="0.0865 0.0265 0.0240"/>
    <axis xyz="0 0 1"/>
    <parent link="right_link8"/>
    <child link="right_hand1"/>
    <dynamics damping="0.7"/>
  </joint>
  <joint name="right_hand_joint2" type="revolute">
    <limit effort="1000.0" lower="-1.57079632679" upper="1.57079632679" velocity="9.42477796077"/>
    <origin rpy="0 0 0" xyz="0.0865 0 0.024"/>
    <axis xyz="0 0 1"/>
    <parent link="right_link8"/>
    <child link="right_hand2"/>
    <dynamics damping="0.7"/>
  </joint>
  <!-- Grasping frame -->
  <link name="rightgrasping_frame"/>
  <joint name="rightgrasping_frame_joint" type="fixed">
    <parent link="right_link8"/>
    <child link="rightgrasping_frame"/>
    <origin rpy="0 0 0" xyz="0.1565 0.0265 0.0240"/>
  </joint>
  <!-- ///////////////////   Transmissions for ROS Control /////////////////// -->
  <transmission name="right_tran1">
    <type>transmission_interface/SimpleTransmission</type>
    <joint name="right_joint1">
      <hardwareInterface>hardware_interface/PositionJointInterface</hardwareInterface>
    </joint>
    <actuator name="right_motor1">
      <hardwareInterface>hardware_interface/PositionJointInterface</hardwareInterface>
      <mechanicalReduction>1</mechanicalReduction>
    </actuator>
  </transmission>
  <transmission name="right_tran2">
    <type>transmission_interface/SimpleTransmission</type>
    <joint name="right_joint2">
      <hardwareInterface>hardware_interface/PositionJointInterface</hardwareInterface>
    </joint>
    <actuator name="right_motor2">
      <hardwareInterface>hardware_interface/PositionJointInterface</hardwareInterface>
      <mechanicalReduction>1</mechanicalReduction>
    </actuator>
  </transmission>
  <transmission name="right_tran3">
    <type>transmission_interface/SimpleTransmission</type>
    <joint name="right_joint3">
      <hardwareInterface>hardware_interface/PositionJointInterface</hardwareInterface>
    </joint>
    <actuator name="right_motor3">
      <hardwareInterface>hardware_interface/PositionJointInterface</hardwareInterface>
      <mechanicalReduction>1</mechanicalReduction>
    </actuator>
  </transmission>
  <transmission name="right_tran4">
    <type>transmission_interface/SimpleTransmission</type>
    <joint name="right_joint4">
      <hardwareInterface>hardware_interface/PositionJointInterface</hardwareInterface>
    </joint>
    <actuator name="right_motor4">
      <hardwareInterface>hardware_interface/PositionJointInterface</hardwareInterface>
      <mechanicalReduction>1</mechanicalReduction>
    </actuator>
  </transmission>
  <transmission name="right_tran5">
    <type>transmission_interface/SimpleTransmission</type>
    <joint name="right_joint5">
      <hardwareInterface>hardware_interface/PositionJointInterface</hardwareInterface>
    </joint>
    <actuator name="right_motor5">
      <hardwareInterface>hardware_interface/PositionJointInterface</hardwareInterface>
      <mechanicalReduction>1</mechanicalReduction>
    </actuator>
  </transmission>
  <transmission name="right_tran6">
    <type>transmission_interface/SimpleTransmission</type>
    <joint name="right_joint6">
      <hardwareInterface>hardware_interface/PositionJointInterface</hardwareInterface>
    </joint>
    <actuator name="right_motor6">
      <hardwareInterface>hardware_interface/PositionJointInterface</hardwareInterface>
      <mechanicalReduction>1</mechanicalReduction>
    </actuator>
  </transmission>
  <transmission name="right_tran7">
    <type>transmission_interface/SimpleTransmission</type>
    <joint name="right_joint7">
      <hardwareInterface>hardware_interface/PositionJointInterface</hardwareInterface>
    </joint>
    <actuator name="right_motor7">
      <hardwareInterface>hardware_interface/PositionJointInterface</hardwareInterface>
      <mechanicalReduction>1</mechanicalReduction>
    </actuator>
  </transmission>
  <transmission name="right_tran8">
    <type>transmission_interface/SimpleTransmission</type>
    <joint name="right_hand_joint1">
      <hardwareInterface>hardware_interface/PositionJointInterface</hardwareInterface>
    </joint>
    <actuator name="right_motor8">
      <hardwareInterface>hardware_interface/PositionJointInterface</hardwareInterface>
      <mechanicalReduction>1</mechanicalReduction>
    </actuator>
  </transmission>
  <transmission name="right_tran9">
    <type>transmission_interface/SimpleTransmission</type>
    <joint name="right_hand_joint2">
      <hardwareInterface>hardware_interface/PositionJointInterface</hardwareInterface>
    </joint>
    <actuator name="right_motor9">
      <hardwareInterface>hardware_interface/PositionJointInterface</hardwareInterface>
      <mechanicalReduction>1</mechanicalReduction>
    </actuator>
  </transmission>
  <link name="left_link1">
    <visual>
      <geometry>
        <mesh filename="package://bmirobot_description/modle/stl_V5/baselink.dae"/>
      </geometry>
      <origin rpy="0 0 0" xyz="0 0 0"/>
      <material name="red"/>
    </visual>
    <collision>
      <geometry>
        <mesh filename="package://bmirobot_description/modle/stl_V5/baselink.dae"/>
      </geometry>
      <origin rpy="0 0 0" xyz="0 0 0"/>
    </collision>
    <inertial>
      <origin rpy="0 0 0" xyz="0 0 1"/>
      <mass value="1"/>
      <inertia ixx="1.0" ixy="0.0" ixz="0.0" iyy="1.0" iyz="0.0" izz="1.0"/>
    </inertial>
  </link>
  <link name="left_link2">
    <visual>
      <geometry>
        <mesh filename="package://bmirobot_description/modle/stl_V5/link1.dae"/>
      </geometry>
      <origin rpy="0 0 0" xyz="0 0 0"/>
      <material name="white"/>
    </visual>
    <collision>
      <geometry>
        <mesh filename="package://bmirobot_description/modle/stl_V5/link1.dae"/>
      </geometry>
      <origin rpy="0 0 0" xyz="0 0 0"/>
    </collision>
    <inertial>
      <origin rpy="0 0 0" xyz="0 0 1"/>
      <mass value="1"/>
      <inertia ixx="1.0" ixy="0.0" ixz="0.0" iyy="1.0" iyz="0.0" izz="1.0"/>
    </inertial>
  </link>
  <link name="left_link3">
    <visual>
      <geometry>
        <mesh filename="package://bmirobot_description/modle/stl_V5/link2.dae"/>
      </geometry>
      <origin rpy="0 0 0" xyz="0 0 0"/>
      <material name="blue"/>
    </visual>
    <collision>
      <geometry>
        <mesh filename="package://bmirobot_description/modle/stl_V5/link2.dae"/>
      </geometry>
      <origin rpy="0 0 0" xyz="0 0 0"/>
    </collision>
    <inertial>
      <origin rpy="0 0 0" xyz="0 0 1"/>
      <mass value="1"/>
      <inertia ixx="1.0" ixy="0.0" ixz="0.0" iyy="1.0" iyz="0.0" izz="1.0"/>
    </inertial>
  </link>
  <link name="left_link4">
    <visual>
      <geometry>
        <mesh filename="package://bmirobot_description/modle/stl_V5/link3.dae"/>
      </geometry>
      <origin rpy="0 0 0" xyz="0 0 0"/>
      <material name="orange"/>
    </visual>
    <collision>
      <geometry>
        <mesh filename="package://bmirobot_description/modle/stl_V5/link3.dae"/>
      </geometry>
      <origin rpy="0 0 0" xyz="0 0 0"/>
    </collision>
    <inertial>
      <origin rpy="0 0 0" xyz="0 0 1"/>
      <mass value="1"/>
      <inertia ixx="1.0" ixy="0.0" ixz="0.0" iyy="1.0" iyz="0.0" izz="1.0"/>
    </inertial>
  </link>
  <link name="left_link5">
    <visual>
      <geometry>
        <mesh filename="package://bmirobot_description/modle/stl_V5/link4.dae"/>
      </geometry>
      <origin rpy="0 0 0" xyz="0 0 0"/>
      <material name="blue"/>
    </visual>
    <collision>
      <geometry>
        <mesh filename="package://bmirobot_description/modle/stl_V5/link4.dae"/>
      </geometry>
      <origin rpy="0 0 0" xyz="0 0 0"/>
    </collision>
    <inertial>
      <origin rpy="0 0 0" xyz="0 0 1"/>
      <mass value="1"/>
      <inertia ixx="1.0" ixy="0.0" ixz="0.0" iyy="1.0" iyz="0.0" izz="1.0"/>
    </inertial>
  </link>
  <link name="left_link6">
    <visual>
      <geometry>
        <mesh filename="package://bmirobot_description/modle/stl_V5/link5.dae"/>
      </geometry>
      <origin rpy="0 0 0" xyz="0 0 0"/>
      <material name="orange"/>
    </visual>
    <collision>
      <geometry>
        <mesh filename="package://bmirobot_description/modle/stl_V5/link5.dae"/>
      </geometry>
      <origin rpy="0 0 0" xyz="0 0 0"/>
    </collision>
    <inertial>
      <origin rpy="0 0 0" xyz="0 0 1"/>
      <mass value="1"/>
      <inertia ixx="1.0" ixy="0.0" ixz="0.0" iyy="1.0" iyz="0.0" izz="1.0"/>
    </inertial>
  </link>
  <link name="left_link7">
    <visual>
      <geometry>
        <mesh filename="package://bmirobot_description/modle/stl_V5/link6.dae"/>
      </geometry>
      <origin rpy="0 0 0" xyz="0 0 0"/>
      <material name="blue"/>
    </visual>
    <collision>
      <geometry>
        <mesh filename="package://bmirobot_description/modle/stl_V5/link6.dae"/>
      </geometry>
      <origin rpy="0 0 0" xyz="0 0 0"/>
    </collision>
    <inertial>
      <origin rpy="0 0 0" xyz="0 0 1"/>
      <mass value="1"/>
      <inertia ixx="1.0" ixy="0.0" ixz="0.0" iyy="1.0" iyz="0.0" izz="1.0"/>
    </inertial>
  </link>
  <link name="left_link8">
    <visual>
      <geometry>
        <mesh filename="package://bmirobot_description/modle/stl_V5/link7.dae"/>
      </geometry>
      <origin rpy="0 0 0" xyz="0 0 0"/>
      <material name="red"/>
    </visual>
    <collision>
      <geometry>
        <mesh filename="package://bmirobot_description/modle/stl_V5/link7.dae"/>
      </geometry>
      <origin rpy="0 0 0" xyz="0 0 0"/>
    </collision>
    <inertial>
      <origin rpy="0 0 0" xyz="0 0 1"/>
      <mass value="1"/>
      <inertia ixx="1.0" ixy="0.0" ixz="0.0" iyy="1.0" iyz="0.0" izz="1.0"/>
    </inertial>
  </link>
  <link name="left_hand1">
    <visual>
      <geometry>
        <mesh filename="package://bmirobot_description/modle/stl_V5/hand-1.dae"/>
      </geometry>
      <origin rpy="0 0 0" xyz="0 0 0"/>
      <material name="white"/>
    </visual>
    <collision>
      <geometry>
        <mesh filename="package://bmirobot_description/modle/stl_V5/hand-1.dae"/>
      </geometry>
      <origin rpy="0 0 0" xyz="0 0 0"/>
    </collision>
    <inertial>
      <origin rpy="0 0 0" xyz="0 0 1"/>
      <mass value="1"/>
      <inertia ixx="1.0" ixy="0.0" ixz="0.0" iyy="1.0" iyz="0.0" izz="1.0"/>
    </inertial>
  </link>
  <link name="left_hand2">
    <visual>
      <geometry>
        <mesh filename="package://bmirobot_description/modle/stl_V5/hand-2.dae"/>
      </geometry>
      <origin rpy="0 0 0" xyz="0 0 0"/>
      <material name="white"/>
    </visual>
    <collision>
      <geometry>
        <mesh filename="package://bmirobot_description/modle/stl_V5/hand-2.dae"/>
      </geometry>
      <origin rpy="0 0 0" xyz="0 0 0"/>
    </collision>
    <inertial>
      <origin rpy="0 0 0" xyz="0 0 1"/>
      <mass value="1"/>
      <inertia ixx="1.0" ixy="0.0" ixz="0.0" iyy="1.0" iyz="0.0" izz="1.0"/>
    </inertial>
  </link>
  <joint name="left_joint1" type="revolute">
    <limit effort="1000.0" lower="-1.57079632679" upper="3.14159265359" velocity="9.42477796077"/>
    <origin rpy="0 0 0" xyz="0.081 0 0"/>
    <axis xyz="1 0 0"/>
    <parent link="left_link1"/>
    <child link="left_link2"/>
    <dynamics damping="0.7"/>
  </joint>
  <joint name="left_joint2" type="revolute">
    <limit effort="1000.0" lower="-3.14159265359" upper="0.174532925199" velocity="9.42477796077"/>
    <origin rpy="0 1.57079632679 0" xyz="0.040 0 0"/>
    <axis xyz="0 1 0"/>
    <parent link="left_link2"/>
    <child link="left_link3"/>
    <dynamics damping="0.7"/>
  </joint>
  <joint name="left_joint3" type="revolute">
    <limit effort="1000.0" lower="-1.57079632679" upper="1.57079632679" velocity="9.42477796077"/>
    <origin rpy="1.57079632679 0 0" xyz="0.0555 0 0"/>
    <axis xyz="1 0 0"/>
    <parent link="left_link3"/>
    <child link="left_link4"/>
    <dynamics damping="0.7"/>
  </joint>
  <joint name="left_joint4" type="revolute">
    <limit effort="1000.0" lower="-0.872664625997" upper="2.09439510239" velocity="9.42477796077"/>
    <origin rpy="0 -1.57079632679 0" xyz="0.1945 0 0"/>
    <axis xyz="0 1 0"/>
    <parent link="left_link4"/>
    <child link="left_link5"/>
    <dynamics damping="0.7"/>
  </joint>
  <joint name="left_joint5" type="revolute">
    <limit effort="1000.0" lower="-3.14159265359" upper="1.74532925199" velocity="9.42477796077"/>
    <origin rpy="1.57079632679 0 0" xyz="0.037 0 0.000"/>
    <axis xyz="1 0 0"/>
    <parent link="left_link5"/>
    <child link="left_link6"/>
    <dynamics damping="0.7"/>
  </joint>
  <joint name="left_joint6" type="revolute">
    <limit effort="1000.0" lower="-1.2217304764" upper="1.57079632679" velocity="9.42477796077"/>
    <origin rpy="-1.57079632679 0 0" xyz="0.203 0 0"/>
    <axis xyz="0 1 0"/>
    <parent link="left_link6"/>
    <child link="left_link7"/>
    <dynamics damping="0.7"/>
  </joint>
  <joint name="left_joint7" type="revolute">
    <limit effort="1000.0" lower="-1.57079632679" upper="1.57079632679" velocity="9.42477796077"/>
    <origin rpy="0.0 0 0" xyz="0.0 0 0"/>
    <axis xyz="0 0 1"/>
    <parent link="left_link7"/>
    <child link="left_link8"/>
    <dynamics damping="0.7"/>
  </joint>
  <joint name="left_hand_joint1" type="revolute">
    <limit effort="1000.0" lower="-1.74532925199" upper="1.74532925199" velocity="9.42477796077"/>
    <origin rpy="0 0 0" xyz="0.0865 0.0265 0.0240"/>
    <axis xyz="0 0 1"/>
    <parent link="left_link8"/>
    <child link="left_hand1"/>
    <dynamics damping="0.7"/>
  </joint>
  <joint name="left_hand_joint2" type="revolute">
    <limit effort="1000.0" lower="-0.785398163397" upper="0.0" velocity="9.42477796077"/>
    <origin rpy="0 0 0" xyz="0.0865 0 0.024"/>
    <axis xyz="0 0 1"/>
    <parent link="left_link8"/>
    <child link="left_hand2"/>
    <dynamics damping="0.7"/>
  </joint>
  <!-- Grasping frame -->
  <link name="leftgrasping_frame"/>
  <joint name="leftgrasping_frame_joint" type="fixed">
    <parent link="left_link8"/>
    <child link="leftgrasping_frame"/>
    <origin rpy="0 0 0" xyz="0.1565 0.0265 0.0240"/>
  </joint>
  <!-- ///////////////////   Transmissions for ROS Control /////////////////// -->
  <transmission name="left_tran1">
    <type>transmission_interface/SimpleTransmission</type>
    <joint name="left_joint1">
      <hardwareInterface>hardware_interface/PositionJointInterface</hardwareInterface>
    </joint>
    <actuator name="left_motor1">
      <hardwareInterface>hardware_interface/PositionJointInterface</hardwareInterface>
      <mechanicalReduction>1</mechanicalReduction>
    </actuator>
  </transmission>
  <transmission name="left_tran2">
    <type>transmission_interface/SimpleTransmission</type>
    <joint name="left_joint2">
      <hardwareInterface>hardware_interface/PositionJointInterface</hardwareInterface>
    </joint>
    <actuator name="left_motor2">
      <hardwareInterface>hardware_interface/PositionJointInterface</hardwareInterface>
      <mechanicalReduction>1</mechanicalReduction>
    </actuator>
  </transmission>
  <transmission name="left_tran3">
    <type>transmission_interface/SimpleTransmission</type>
    <joint name="left_joint3">
      <hardwareInterface>hardware_interface/PositionJointInterface</hardwareInterface>
    </joint>
    <actuator name="left_motor3">
      <hardwareInterface>hardware_interface/PositionJointInterface</hardwareInterface>
      <mechanicalReduction>1</mechanicalReduction>
    </actuator>
  </transmission>
  <transmission name="left_tran4">
    <type>transmission_interface/SimpleTransmission</type>
    <joint name="left_joint4">
      <hardwareInterface>hardware_interface/PositionJointInterface</hardwareInterface>
    </joint>
    <actuator name="left_motor4">
      <hardwareInterface>hardware_interface/PositionJointInterface</hardwareInterface>
      <mechanicalReduction>1</mechanicalReduction>
    </actuator>
  </transmission>
  <transmission name="left_tran5">
    <type>transmission_interface/SimpleTransmission</type>
    <joint name="left_joint5">
      <hardwareInterface>hardware_interface/PositionJointInterface</hardwareInterface>
    </joint>
    <actuator name="left_motor5">
      <hardwareInterface>hardware_interface/PositionJointInterface</hardwareInterface>
      <mechanicalReduction>1</mechanicalReduction>
    </actuator>
  </transmission>
  <transmission name="left_tran6">
    <type>transmission_interface/SimpleTransmission</type>
    <joint name="left_joint6">
      <hardwareInterface>hardware_interface/PositionJointInterface</hardwareInterface>
    </joint>
    <actuator name="left_motor6">
      <hardwareInterface>hardware_interface/PositionJointInterface</hardwareInterface>
      <mechanicalReduction>1</mechanicalReduction>
    </actuator>
  </transmission>
  <transmission name="left_tran7">
    <type>transmission_interface/SimpleTransmission</type>
    <joint name="left_joint7">
      <hardwareInterface>hardware_interface/PositionJointInterface</hardwareInterface>
    </joint>
    <actuator name="left_motor7">
      <hardwareInterface>hardware_interface/PositionJointInterface</hardwareInterface>
      <mechanicalReduction>1</mechanicalReduction>
    </actuator>
  </transmission>
  <transmission name="left_tran8">
    <type>transmission_interface/SimpleTransmission</type>
    <joint name="left_hand_joint1">
      <hardwareInterface>hardware_interface/PositionJointInterface</hardwareInterface>
    </joint>
    <actuator name="left_motor8">
      <hardwareInterface>hardware_interface/PositionJointInterface</hardwareInterface>
      <mechanicalReduction>1</mechanicalReduction>
    </actuator>
  </transmission>
  <transmission name="left_tran9">
    <type>transmission_interface/SimpleTransmission</type>
    <joint name="left_hand_joint2">
      <hardwareInterface>hardware_interface/PositionJointInterface</hardwareInterface>
    </joint>
    <actuator name="left_motor9">
      <hardwareInterface>hardware_interface/PositionJointInterface</hardwareInterface>
      <mechanicalReduction>1</mechanicalReduction>
    </actuator>
  </transmission>
  <!--
    <plugin name="gazebo_ros_power_monitor_controller" filename="libgazebo_ros_power_monitor.so">
      <alwaysOn>true</alwaysOn>
      <updateRate>1.0</updateRate>
      <timeout>5</timeout>
      <powerStateTopic>power_state</powerStateTopic>
      <powerStateRate>10.0</powerStateRate>
      <fullChargeCapacity>87.78</fullChargeCapacity>     
      <dischargeRate>-474</dischargeRate>
      <chargeRate>525</chargeRate>
      <dischargeVoltage>15.52</dischargeVoltage>
      <chargeVoltage>16.41</chargeVoltage>
    </plugin>
-->
</robot>

